<?xml version="1.0"?>
<robot name="esibot" xmlns:xacro="http://www.ros.org/wiki/xacro">
  <!-- ESIBOT robot description.
       Frames follow REP-103: X forward, Y left, Z up.
       The driver publishes odom -> base_footprint; robot_state_publisher
       provides base_footprint -> base_link and all fixed sensor frames. -->

  <xacro:property name="pi" value="3.141592653589793"/>

  <!-- Chassis measured/derived from project files and visual references. -->
  <xacro:property name="plate_x" value="0.182"/>
  <xacro:property name="plate_y" value="0.126"/>
  <xacro:property name="plate_z" value="0.003"/>
  <xacro:property name="wheel_radius" value="0.033"/>
  <xacro:property name="wheel_width" value="0.026"/>
  <xacro:property name="wheel_separation" value="0.170"/>
  <xacro:property name="axle_x" value="-0.030"/>
  <xacro:property name="upper_deck_z" value="0.060"/>
  <xacro:property name="deck_center_x" value="${-axle_x}"/>
  <xacro:property name="caster_radius" value="0.012"/>

  <xacro:property name="servo_height" value="0.027"/>
  <xacro:property name="radar_plate_x" value="0.082"/>
  <xacro:property name="radar_plate_y" value="0.082"/>
  <xacro:property name="radar_plate_z" value="0.004"/>
  <xacro:property name="sonar_radius" value="0.008"/>
  <xacro:property name="sonar_arm" value="0.041"/>

  <xacro:macro name="box_inertia" params="mass x y z">
    <inertia ixx="${mass * (y*y + z*z) / 12.0}" ixy="0" ixz="0"
             iyy="${mass * (x*x + z*z) / 12.0}" iyz="0"
             izz="${mass * (x*x + y*y) / 12.0}"/>
  </xacro:macro>

  <xacro:macro name="cylinder_inertia" params="mass radius length">
    <inertia ixx="${mass * (3*radius*radius + length*length) / 12.0}" ixy="0" ixz="0"
             iyy="${mass * (3*radius*radius + length*length) / 12.0}" iyz="0"
             izz="${mass * radius*radius / 2.0}"/>
  </xacro:macro>

  <xacro:macro name="sphere_inertia" params="mass radius">
    <inertia ixx="${2.0 * mass * radius*radius / 5.0}" ixy="0" ixz="0"
             iyy="${2.0 * mass * radius*radius / 5.0}" iyz="0"
             izz="${2.0 * mass * radius*radius / 5.0}"/>
  </xacro:macro>

  <material name="white_acrylic">
    <color rgba="0.92 0.92 0.88 1.0"/>
  </material>
  <material name="black_plastic">
    <color rgba="0.02 0.02 0.02 1.0"/>
  </material>
  <material name="yellow_wheel">
    <color rgba="1.00 0.78 0.02 1.0"/>
  </material>
  <material name="rubber">
    <color rgba="0.03 0.03 0.03 1.0"/>
  </material>
  <material name="metal">
    <color rgba="0.70 0.70 0.72 1.0"/>
  </material>
  <material name="pcb_green">
    <color rgba="0.05 0.38 0.16 1.0"/>
  </material>
  <material name="driver_blue">
    <color rgba="0.04 0.17 0.65 1.0"/>
  </material>
  <material name="camera_black">
    <color rgba="0.01 0.01 0.01 1.0"/>
  </material>
  <material name="imu_blue">
    <color rgba="0.10 0.30 0.95 1.0"/>
  </material>
  <material name="sonar_pcb">
    <color rgba="0.02 0.12 0.11 1.0"/>
  </material>
  <material name="sonar_can">
    <color rgba="0.68 0.68 0.66 1.0"/>
  </material>
  <link name="base_footprint"/>

  <joint name="base_joint" type="fixed">
    <parent link="base_footprint"/>
    <child link="base_link"/>
    <origin xyz="0 0 ${wheel_radius}" rpy="0 0 0"/>
  </joint>

  <link name="base_link">
    <visual>
      <origin xyz="${deck_center_x} 0 0" rpy="0 0 0"/>
      <geometry>
        <box size="${plate_x} ${plate_y} ${plate_z}"/>
      </geometry>
      <material name="white_acrylic"/>
    </visual>
    <collision>
      <origin xyz="${deck_center_x} 0 0" rpy="0 0 0"/>
      <geometry>
        <box size="${plate_x} ${plate_y} ${plate_z}"/>
      </geometry>
    </collision>
    <inertial>
      <origin xyz="${deck_center_x} 0 0" rpy="0 0 0"/>
      <mass value="0.30"/>
      <xacro:box_inertia mass="0.30" x="${plate_x}" y="${plate_y}" z="${plate_z}"/>
    </inertial>
  </link>

  <xacro:macro name="standoff" params="name x y">
    <link name="${name}_standoff_link">
      <visual>
        <geometry>
          <cylinder radius="0.004" length="${upper_deck_z}"/>
        </geometry>
        <material name="white_acrylic"/>
      </visual>
      <collision>
        <geometry>
          <cylinder radius="0.004" length="${upper_deck_z}"/>
        </geometry>
      </collision>
      <inertial>
        <mass value="0.008"/>
        <xacro:cylinder_inertia mass="0.008" radius="0.004" length="${upper_deck_z}"/>
      </inertial>
    </link>
    <joint name="${name}_standoff_joint" type="fixed">
      <parent link="base_link"/>
      <child link="${name}_standoff_link"/>
      <origin xyz="${deck_center_x + x} ${y} ${plate_z/2.0 + upper_deck_z/2.0}" rpy="0 0 0"/>
    </joint>
  </xacro:macro>

  <xacro:standoff name="front_left" x="0.075" y="0.050"/>
  <xacro:standoff name="front_right" x="0.075" y="-0.050"/>
  <xacro:standoff name="rear_left" x="-0.075" y="0.050"/>
  <xacro:standoff name="rear_right" x="-0.075" y="-0.050"/>

  <link name="upper_deck_link">
    <visual>
      <origin xyz="${deck_center_x} 0 0" rpy="0 0 0"/>
      <geometry>
        <box size="${plate_x} ${plate_y} ${plate_z}"/>
      </geometry>
      <material name="white_acrylic"/>
    </visual>
    <collision>
      <origin xyz="${deck_center_x} 0 0" rpy="0 0 0"/>
      <geometry>
        <box size="${plate_x} ${plate_y} ${plate_z}"/>
      </geometry>
    </collision>
    <inertial>
      <origin xyz="${deck_center_x} 0 0" rpy="0 0 0"/>
      <mass value="0.18"/>
      <xacro:box_inertia mass="0.18" x="${plate_x}" y="${plate_y}" z="${plate_z}"/>
    </inertial>
  </link>

  <joint name="upper_deck_joint" type="fixed">
    <parent link="base_link"/>
    <child link="upper_deck_link"/>
    <origin xyz="0 0 ${plate_z + upper_deck_z}" rpy="0 0 0"/>
  </joint>

  <xacro:macro name="drive_wheel" params="side y_sign">
    <link name="${side}_wheel_link">
      <visual>
        <origin xyz="0 0 0" rpy="${pi/2.0} 0 0"/>
        <geometry>
          <cylinder radius="${wheel_radius}" length="${wheel_width}"/>
        </geometry>
        <material name="rubber"/>
      </visual>
      <visual>
        <origin xyz="0 ${y_sign * (wheel_width/2.0 + 0.002)} 0" rpy="${pi/2.0} 0 0"/>
        <geometry>
          <cylinder radius="${wheel_radius * 0.68}" length="0.004"/>
        </geometry>
        <material name="yellow_wheel"/>
      </visual>
      <collision>
        <origin xyz="0 0 0" rpy="${pi/2.0} 0 0"/>
        <geometry>
          <cylinder radius="${wheel_radius}" length="${wheel_width}"/>
        </geometry>
      </collision>
      <inertial>
        <origin xyz="0 0 0" rpy="${pi/2.0} 0 0"/>
        <mass value="0.06"/>
        <xacro:cylinder_inertia mass="0.06" radius="${wheel_radius}" length="${wheel_width}"/>
      </inertial>
    </link>

    <joint name="${side}_wheel_joint" type="continuous">
      <parent link="base_link"/>
      <child link="${side}_wheel_link"/>
      <origin xyz="0 ${y_sign * wheel_separation/2.0} 0" rpy="0 0 0"/>
      <axis xyz="0 1 0"/>
      <dynamics damping="0.1" friction="0.05"/>
    </joint>

    <link name="${side}_encoder_link">
      <visual>
        <origin xyz="0 0 0" rpy="${pi/2.0} 0 0"/>
        <geometry>
          <cylinder radius="0.013" length="0.006"/>
        </geometry>
        <material name="black_plastic"/>
      </visual>
      <inertial>
        <mass value="0.004"/>
        <xacro:cylinder_inertia mass="0.004" radius="0.013" length="0.006"/>
      </inertial>
    </link>

    <joint name="${side}_encoder_joint" type="fixed">
      <parent link="${side}_wheel_link"/>
      <child link="${side}_encoder_link"/>
      <origin xyz="0 ${-y_sign * (wheel_width/2.0 + 0.008)} 0" rpy="0 0 0"/>
    </joint>
  </xacro:macro>

  <xacro:drive_wheel side="left" y_sign="1"/>
  <xacro:drive_wheel side="right" y_sign="-1"/>

  <link name="caster_wheel_link">
    <visual>
      <geometry>
        <sphere radius="${caster_radius}"/>
      </geometry>
      <material name="black_plastic"/>
    </visual>
    <collision>
      <geometry>
        <sphere radius="${caster_radius}"/>
      </geometry>
    </collision>
    <inertial>
      <mass value="0.02"/>
      <xacro:sphere_inertia mass="0.02" radius="${caster_radius}"/>
    </inertial>
  </link>

  <joint name="caster_wheel_joint" type="fixed">
    <parent link="base_link"/>
    <child link="caster_wheel_link"/>
    <origin xyz="${deck_center_x + plate_x/2.0 - 0.018} 0 ${caster_radius - wheel_radius}" rpy="0 0 0"/>
  </joint>

  <link name="raspberry_pi_link">
    <visual>
      <geometry>
        <box size="0.085 0.056 0.017"/>
      </geometry>
      <material name="pcb_green"/>
    </visual>
    <collision>
      <geometry>
        <box size="0.085 0.056 0.017"/>
      </geometry>
    </collision>
    <inertial>
      <mass value="0.046"/>
      <xacro:box_inertia mass="0.046" x="0.085" y="0.056" z="0.017"/>
    </inertial>
  </link>

  <joint name="raspberry_pi_joint" type="fixed">
    <parent link="base_link"/>
    <child link="raspberry_pi_link"/>
    <origin xyz="${deck_center_x + 0.010} 0.026 ${plate_z/2.0 + 0.0085}" rpy="0 0 0"/>
  </joint>

  <link name="l298n_link">
    <visual>
      <geometry>
        <box size="0.043 0.043 0.026"/>
      </geometry>
      <material name="driver_blue"/>
    </visual>
    <collision>
      <geometry>
        <box size="0.043 0.043 0.026"/>
      </geometry>
    </collision>
    <inertial>
      <mass value="0.030"/>
      <xacro:box_inertia mass="0.030" x="0.043" y="0.043" z="0.026"/>
    </inertial>
  </link>

  <joint name="l298n_joint" type="fixed">
    <parent link="base_link"/>
    <child link="l298n_link"/>
    <origin xyz="${deck_center_x - 0.040} -0.034 ${plate_z/2.0 + 0.013}" rpy="0 0 0"/>
  </joint>

  <link name="battery_link">
    <visual>
      <geometry>
        <box size="0.095 0.036 0.024"/>
      </geometry>
      <material name="black_plastic"/>
    </visual>
    <collision>
      <geometry>
        <box size="0.095 0.036 0.024"/>
      </geometry>
    </collision>
    <inertial>
      <mass value="0.18"/>
      <xacro:box_inertia mass="0.18" x="0.095" y="0.036" z="0.024"/>
    </inertial>
  </link>

  <joint name="battery_joint" type="fixed">
    <parent link="base_link"/>
    <child link="battery_link"/>
    <origin xyz="${deck_center_x - 0.052} 0.000 ${plate_z/2.0 + 0.012}" rpy="0 0 0"/>
  </joint>

  <link name="imu_link">
    <visual>
      <geometry>
        <box size="0.020 0.016 0.003"/>
      </geometry>
      <material name="imu_blue"/>
    </visual>
    <collision>
      <geometry>
        <box size="0.020 0.016 0.003"/>
      </geometry>
    </collision>
    <inertial>
      <mass value="0.003"/>
      <xacro:box_inertia mass="0.003" x="0.020" y="0.016" z="0.003"/>
    </inertial>
  </link>

  <joint name="imu_joint" type="fixed">
    <parent link="base_link"/>
    <child link="imu_link"/>
    <origin xyz="${deck_center_x + 0.018} -0.018 ${plate_z/2.0 + 0.0015}" rpy="0 0 0"/>
  </joint>

  <link name="raspi_camera_link">
    <visual>
      <geometry>
        <box size="0.025 0.024 0.004"/>
      </geometry>
      <material name="pcb_green"/>
    </visual>
    <visual>
      <origin xyz="0.014 0 0.003" rpy="0 ${pi/2.0} 0"/>
      <geometry>
        <cylinder radius="0.007" length="0.006"/>
      </geometry>
      <material name="camera_black"/>
    </visual>
    <visual>
      <origin xyz="-0.004 0 -0.005" rpy="0 0 0"/>
      <geometry>
        <box size="0.018 0.012 0.006"/>
      </geometry>
      <material name="camera_black"/>
    </visual>
    <collision>
      <geometry>
        <box size="0.025 0.024 0.010"/>
      </geometry>
    </collision>
    <inertial>
      <mass value="0.006"/>
      <xacro:box_inertia mass="0.006" x="0.025" y="0.024" z="0.010"/>
    </inertial>
  </link>

  <joint name="raspi_camera_joint" type="fixed">
    <parent link="upper_deck_link"/>
    <child link="raspi_camera_link"/>
    <origin xyz="${deck_center_x + 0.058} -0.030 ${plate_z/2.0 + 0.010}" rpy="0 0 0"/>
  </joint>

  <link name="camera_link">
    <inertial>
      <mass value="0.001"/>
      <xacro:box_inertia mass="0.001" x="0.001" y="0.001" z="0.001"/>
    </inertial>
  </link>

  <joint name="camera_joint" type="fixed">
    <parent link="raspi_camera_link"/>
    <child link="camera_link"/>
    <origin xyz="0.017 0 0.003" rpy="0 0 0"/>
  </joint>

  <link name="servo_link">
    <visual>
      <geometry>
        <box size="0.023 0.012 ${servo_height}"/>
      </geometry>
      <material name="black_plastic"/>
    </visual>
    <collision>
      <geometry>
        <box size="0.023 0.012 ${servo_height}"/>
      </geometry>
    </collision>
    <inertial>
      <mass value="0.055"/>
      <xacro:box_inertia mass="0.055" x="0.023" y="0.012" z="${servo_height}"/>
    </inertial>
  </link>

  <joint name="servo_joint" type="revolute">
    <parent link="upper_deck_link"/>
    <child link="servo_link"/>
    <origin xyz="${deck_center_x + 0.005} 0 ${plate_z/2.0 + servo_height/2.0}" rpy="0 0 0"/>
    <axis xyz="0 0 1"/>
    <limit lower="0.0" upper="${pi}" effort="0.4" velocity="3.14"/>
    <dynamics damping="0.05" friction="0.01"/>
  </joint>

  <link name="radar_platform_link">
    <visual>
      <geometry>
        <box size="${radar_plate_x} ${radar_plate_y} ${radar_plate_z}"/>
      </geometry>
      <material name="white_acrylic"/>
    </visual>
    <collision>
      <geometry>
        <box size="${radar_plate_x} ${radar_plate_y} ${radar_plate_z}"/>
      </geometry>
    </collision>
    <inertial>
      <mass value="0.020"/>
      <xacro:box_inertia mass="0.020" x="${radar_plate_x}" y="${radar_plate_y}" z="${radar_plate_z}"/>
    </inertial>
  </link>

  <joint name="radar_platform_joint" type="fixed">
    <parent link="servo_link"/>
    <child link="radar_platform_link"/>
    <origin xyz="0 0 ${servo_height/2.0 + radar_plate_z/2.0}" rpy="0 0 0"/>
  </joint>

  <link name="radar_link">
    <inertial>
      <mass value="0.001"/>
      <xacro:sphere_inertia mass="0.001" radius="0.001"/>
    </inertial>
  </link>

  <joint name="radar_joint" type="fixed">
    <parent link="radar_platform_link"/>
    <child link="radar_link"/>
    <origin xyz="0 0 ${radar_plate_z/2.0 + 0.009}" rpy="0 0 0"/>
  </joint>

  <xacro:macro name="sonar_module" params="name yaw">
    <link name="${name}_ultrasonic_link">
      <visual>
        <origin xyz="0 0 0" rpy="0 0 0"/>
        <geometry>
          <box size="0.012 0.046 0.020"/>
        </geometry>
        <material name="sonar_pcb"/>
      </visual>
      <visual>
        <origin xyz="0.008 0.011 0" rpy="0 ${pi/2.0} 0"/>
        <geometry>
          <cylinder radius="${sonar_radius}" length="0.007"/>
        </geometry>
        <material name="sonar_can"/>
      </visual>
      <visual>
        <origin xyz="0.008 -0.011 0" rpy="0 ${pi/2.0} 0"/>
        <geometry>
          <cylinder radius="${sonar_radius}" length="0.007"/>
        </geometry>
        <material name="sonar_can"/>
      </visual>
      <collision>
        <geometry>
          <box size="0.016 0.046 0.020"/>
        </geometry>
      </collision>
      <inertial>
        <mass value="0.010"/>
        <xacro:box_inertia mass="0.010" x="0.016" y="0.046" z="0.020"/>
      </inertial>
    </link>
    <joint name="${name}_ultrasonic_joint" type="fixed">
      <parent link="radar_platform_link"/>
      <child link="${name}_ultrasonic_link"/>
      <origin xyz="${sonar_arm * cos(yaw)} ${sonar_arm * sin(yaw)} ${radar_plate_z/2.0 + 0.010}"
              rpy="0 0 ${yaw}"/>
    </joint>
  </xacro:macro>

  <xacro:sonar_module name="front" yaw="0"/>
  <xacro:sonar_module name="left" yaw="${pi/2.0}"/>
  <xacro:sonar_module name="rear" yaw="${pi}"/>
  <xacro:sonar_module name="right" yaw="${-pi/2.0}"/>

</robot>
